Workbook

Sheet Read Me
A1: Item | B1: Detail
A2: What this is | B2: Keyword clusters and content blueprints for every content page on the Next.js rebuild of radiant-smiles.com. Use with 'Radiant Smiles - Keyword Map & Sitemap.xlsx' (the sitemap master).
A3: How to use it | B3: 1) Page Structure: hub > subpage tree and whether new subpages are needed. 2) Location Strategy: every area, decision and overlaps. 3) Keyword Clusters: every keyword per page with its role and where to use it. 4) Page Blueprint: H1, title, meta, H2 outline, internal links, schema per page. 5) FAQ Bank: questions per page. 6) Content Plan: build order and word counts.
A4: Source: Verified | B4: Volume and KD returned by Semrush MCP, US database, 30 Sep-1 Oct 2026 (green rows). These national and near-me terms were pulled for the ASD project and apply unchanged here.
A5: Source: Agency report | B5: Volumes from the previous agency's rank report (Google Ads, Yardley 19067, Sep 2026) (blue rows). Only 5 local terms had volume; KD not given.
A6: Source: Pending Semrush | B6: Local Yardley, town and NJ terms (yellow rows). The Semrush API unit balance was zero on 6 Oct 2026. Volume/KD left blank on purpose, not estimated. Rerun when units are available.
A7: Scope rule | B7: Services and subpages match the current site. No new service pages. Duplicates merged with 301s. Strong extra topics (e.g. 'smile makeover', 5,400/mo, KD 6) are H2 sections inside existing pages.
A8: Primary keyword rule | B8: Each page has exactly one primary keyword and no keyword is primary on two pages. Most '[service] yardley' primaries are Pending (yellow): the right local pattern, demand unconfirmed until the rerun.
A9: Flag: Invisalign | B9: Use 'invisalign' terms only if the practice is a certified Invisalign provider.
A10: Flag: Pediatric | B10: Children's page targets 'children's dentist'. 'Pediatric dentist' is a comparison phrase only.
A11: Flag: Periodontist | B11: 'periodontist yardley' is listed on Periodontal Services as a search phrase. Never state the practice is a periodontist.
A12: Flag: Unconfirmed claims | B12: Same-day dentures, microscopes, CBCT, iTero, laser therapy, mercury-free fillings, 'since 2009', surgical wisdom teeth: include only after the practice confirms.
... A18: Flag: Office hours | B18: Tuesday shows '8:00 AM - 5:00 AM' on the current site. Confirm all hours.

Sheet Page Structure
A1: Hub | B1: Level | C1: URL | D1: Page | E1: Build tier | F1: Subpages needed?
A2: Core | B2: Page | C2: / | D2: Home | E2: 1 | F2: n/a
A3: Core | B3: Page | C3: /about-us/ | D3: About Us | E3: 1 | F3: Existing children: 2 doctor bios, Meet the Staff, Before & After Gallery. Keep all.
A4: Core | B4: Subpage | C4: /about-us/dr-urvishkumar-bhalala/ | D4: Dr. Urvishkumar Bhalala | E4: 1 | F4: n/a
A5: Core | B5: Subpage | C5: /about-us/dr-jaspreet-gadria-dmd/ | D5: Dr. Jaspreet Gadria | E5: 1 | F5: n/a
A6: Core | B6: Subpage | C6: /about-us/meet-the-staff/ | D6: Meet the Staff | E6: 2 | F6: n/a
A7: Core | B7: Page | C7: /patient-reviews/ | D7: Patient Reviews | E7: 1 | F7: n/a
A8: Core | B8: Subpage | C8: /about-us/before-and-after-gallery/ | D8: Before & After Gallery | E8: 2 | F8: n/a
A9: Core | B9: Page | C9: /special-offers/ | D9: Special Offers | E9: 1 | F9: n/a
A10: Core | B10: Page | C10: /contact-us/ | D10: Contact Us | E10: 1 | F10: n/a
A11: Patient info | B11: Hub | C11: /patient-information/ | D11: Patient Information (hub) | E11: 1 | F11: Keep 11 children. Merge /introduction/, /services/, /first-visit/ and /technology/ (see Redirects tab).
A12: Patient info | B12: Subpage | C12: /patient-information/new-patients/ | D12: New Patients | E12: 1 | F12: n/a
A13: Patient info | B13: Subpage | C13: /patient-information/scheduling/ | D13: Scheduling | E13: 1 | F13: n/a
... A74: Content | B74: Page | C74: /blog/ | D74: Blog hub | E74: 2 | F74: Use Pending-Semrush long-tail and question terms from service pages as blog topics, each linking back to its service page.

Sheet Scope Summary
A1: Hub | B1: Pages | C1: Keywords | D1: Semrush verified | E1: Agency report | F1: Pending Semrush | G1: Primary keywords
A2: Core | B2: =COUNTIF('Page Structure'!A$2:A$74,A2) | C2: =COUNTIF('Keyword Clusters'!B$2:B$330,A2) | D2: =COUNTIFS('Keyword Clusters'!B$2:B$330,A2,'Keyword Clusters'!J$2:J$330,"Semrush verified") | E2: =COUNTIFS('Keyword Clusters'!B$2:B$330,A2,'Keyword Clusters'!J$2:J$330,"Agency report (Google Ads vol)") | F2: =COUNTIFS('Keyword Clusters'!B$2:B$330,A2,'Keyword Clusters'!J$2:J$330,"Pending Semrush") | G2: =COUNTIFS('Keyword Clusters'!B$2:B$330,A2,'Keyword Clusters'!E$2:E$330,"Primary")
A3: Patient info | B3: =COUNTIF('Page Structure'!A$2:A$74,A3) | C3: =COUNTIF('Keyword Clusters'!B$2:B$330,A3) | D3: =COUNTIFS('Keyword Clusters'!B$2:B$330,A3,'Keyword Clusters'!J$2:J$330,"Semrush verified") | E3: =COUNTIFS('Keyword Clusters'!B$2:B$330,A3,'Keyword Clusters'!J$2:J$330,"Agency report (Google Ads vol)") | F3: =COUNTIFS('Keyword Clusters'!B$2:B$330,A3,'Keyword Clusters'!J$2:J$330,"Pending Semrush") | G3: =COUNTIFS('Keyword Clusters'!B$2:B$330,A3,'Keyword Clusters'!E$2:E$330,"Primary")
A4: General dentistry | B4: =COUNTIF('Page Structure'!A$2:A$74,A4) | C4: =COUNTIF('Keyword Clusters'!B$2:B$330,A4) | D4: =COUNTIFS('Keyword Clusters'!B$2:B$330,A4,'Keyword Clusters'!J$2:J$330,"Semrush verified") | E4: =COUNTIFS('Keyword Clusters'!B$2:B$330,A4,'Keyword Clusters'!J$2:J$330,"Agency report (Google Ads vol)") | F4: =COUNTIFS('Keyword Clusters'!B$2:B$330,A4,'Keyword Clusters'!J$2:J$330,"Pending Semrush") | G4: =COUNTIFS('Keyword Clusters'!B$2:B$330,A4,'Keyword Clusters'!E$2:E$330,"Primary")
A5: Preventative care | B5: =COUNTIF('Page Structure'!A$2:A$74,A5) | C5: =COUNTIF('Keyword Clusters'!B$2:B$330,A5) | D5: =COUNTIFS('Keyword Clusters'!B$2:B$330,A5,'Keyword Clusters'!J$2:J$330,"Semrush verified") | E5: =COUNTIFS('Keyword Clusters'!B$2:B$330,A5,'Keyword Clusters'!J$2:J$330,"Agency report (Google Ads vol)") | F5: =COUNTIFS('Keyword Clusters'!B$2:B$330,A5,'Keyword Clusters'!J$2:J$330,"Pending Semrush") | G5: =COUNTIFS('Keyword Clusters'!B$2:B$330,A5,'Keyword Clusters'!E$2:E$330,"Primary")
A6: Restorative | B6: =COUNTIF('Page Structure'!A$2:A$74,A6) | C6: =COUNTIF('Keyword Clusters'!B$2:B$330,A6) | D6: =COUNTIFS('Keyword Clusters'!B$2:B$330,A6,'Keyword Clusters'!J$2:J$330,"Semrush verified") | E6: =COUNTIFS('Keyword Clusters'!B$2:B$330,A6,'Keyword Clusters'!J$2:J$330,"Agency report (Google Ads vol)") | F6: =COUNTIFS('Keyword Clusters'!B$2:B$330,A6,'Keyword Clusters'!J$2:J$330,"Pending Semrush") | G6: =COUNTIFS('Keyword Clusters'!B$2:B$330,A6,'Keyword Clusters'!E$2:E$330,"Primary")
A7: Cosmetic | B7: =COUNTIF('Page Structure'!A$2:A$74,A7) | C7: =COUNTIF('Keyword Clusters'!B$2:B$330,A7) | D7: =COUNTIFS('Keyword Clusters'!B$2:B$330,A7,'Keyword Clusters'!J$2:J$330,"Semrush verified") | E7: =COUNTIFS('Keyword Clusters'!B$2:B$330,A7,'Keyword Clusters'!J$2:J$330,"Agency report (Google Ads vol)") | F7: =COUNTIFS('Keyword Clusters'!B$2:B$330,A7,'Keyword Clusters'!J$2:J$330,"Pending Semrush") | G7: =COUNTIFS('Keyword Clusters'!B$2:B$330,A7,'Keyword Clusters'!E$2:E$330,"Primary")
A8: Location | B8: =COUNTIF('Page Structure'!A$2:A$74,A8) | C8: =COUNTIF('Keyword Clusters'!B$2:B$330,A8) | D8: =COUNTIFS('Keyword Clusters'!B$2:B$330,A8,'Keyword Clusters'!J$2:J$330,"Semrush verified") | E8: =COUNTIFS('Keyword Clusters'!B$2:B$330,A8,'Keyword Clusters'!J$2:J$330,"Agency report (Google Ads vol)") | F8: =COUNTIFS('Keyword Clusters'!B$2:B$330,A8,'Keyword Clusters'!J$2:J$330,"Pending Semrush") | G8: =COUNTIFS('Keyword Clusters'!B$2:B$330,A8,'Keyword Clusters'!E$2:E$330,"Primary")
A9: Service + location | B9: =COUNTIF('Page Structure'!A$2:A$74,A9) | C9: =COUNTIF('Keyword Clusters'!B$2:B$330,A9) | D9: =COUNTIFS('Keyword Clusters'!B$2:B$330,A9,'Keyword Clusters'!J$2:J$330,"Semrush verified") | E9: =COUNTIFS('Keyword Clusters'!B$2:B$330,A9,'Keyword Clusters'!J$2:J$330,"Agency report (Google Ads vol)") | F9: =COUNTIFS('Keyword Clusters'!B$2:B$330,A9,'Keyword Clusters'!J$2:J$330,"Pending Semrush") | G9: =COUNTIFS('Keyword Clusters'!B$2:B$330,A9,'Keyword Clusters'!E$2:E$330,"Primary")
A10: Total | B10: =SUM(B2:B9) | C10: =SUM(C2:C9) | D10: =SUM(D2:D9) | E10: =SUM(E2:E9) | F10: =SUM(F2:F9) | G10: =SUM(G2:G9)

Sheet Location Strategy
A1: Area | B1: Group | C1: ZIP(s) | D1: Approx. drive (verify) | E1: Main routes (verify) | F1: Decision | G1: Page URL | H1: Build tier | I1: Primary keyword | J1: Volume / mo | K1: KD | L1: Source | M1: Service+town page(s) | N1: Notes
A2: All areas (regional hub) | B2: Hub | F2: Own page | G2: /areas-we-serve/ | H2: 1 | I2: dentist near trenton nj | L2: Pending Semrush | M2: /dental-implants-mercer-county-nj/, /emergency-dentist-trenton-nj/, /invisalign-trenton-nj/ | N2: Bucks County terms not used (ASD owns them).
A3: Morrisville | B3: Bucks County PA (practice-listed) | C3: 19067 | D3: 5-10 min | E3: US-1, Big Oak Rd / Pennsylvania Ave | F3: Own page | G3: /dentist-morrisville-pa/ | H3: 1 | I3: dentist morrisville pa | L3: Pending Semrush | N3: Closest town to the office. ZIP 19067 assigned to the homepage (Yardley); this page targets the town name only. Note: ASD's sitemap also lists a Morrisville page (Tier 3) - recommend ASD drops it.
A4: Lower Makefield | B4: Bucks County PA (home township) | C4: 19067 | D4: 0-10 min | E4: Big Oak Rd, Oxford Valley Rd | F4: Own page | G4: /dentist-lower-makefield-pa/ | H4: 2 | I4: dentist lower makefield pa | L4: Pending Semrush | N4: The office is inside Lower Makefield Twp. Homepage owns 'yardley' + ZIP; this page targets the township name only.
A5: Washington Crossing (PA) | B5: Bucks County PA (practice-listed) | C5: 18977 | D5: 15-20 min | E5: PA-32 (River Rd), I-295 | F5: Own page | G5: /dentist-washington-crossing-pa/ | H5: 2 | I5: dentist washington crossing pa | L5: Pending Semrush | N5: Upper Makefield Twp is a section of this page. The NJ side of Washington Crossing (Titusville) goes on the Hopewell NJ page.
A6: New Hope | B6: Bucks County PA (new) | C6: 18938 | D6: 25-30 min | E6: PA-32 (River Rd), I-295 | F6: Own page | G6: /dentist-new-hope-pa/ | H6: 3 | I6: dentist new hope pa | L6: Pending Semrush | N6: Edge of the realistic catchment; expect slower results. Confirm the practice wants patients from here.
A7: Trenton | B7: Mercer County NJ (practice-listed) | C7: 08608-08618 | D7: 15 min | E7: US-1 (Trenton-Morrisville Toll Bridge), Calhoun St Bridge | F7: Own page | G7: /dentist-trenton-nj/ | H7: 1 | I7: dentist trenton nj | L7: Pending Semrush | M7: /emergency-dentist-trenton-nj/, /invisalign-trenton-nj/ | N7: Largest population in the catchment. NJ patients cross one bridge. Don't claim NJ Medicaid/FamilyCare acceptance unless confirmed.
A8: Ewing | B8: Mercer County NJ (practice-listed) | C8: 08618, 08628, 08638 | D8: 15-20 min | E8: I-295 (Scudder Falls Bridge), PA-332 | F8: Own page | G8: /dentist-ewing-nj/ | H8: 1 | I8: dentist ewing nj | L8: Pending Semrush | N8: West Trenton (08628) is a section of this page. Scudder Falls Bridge (I-295) makes this a short drive.
A9: Hamilton | B9: Mercer County NJ (new) | C9: 08609-08620, 08690, 08691 | D9: 20-25 min | E9: US-1, I-295, NJ-33 | F9: Own page | G9: /dentist-hamilton-nj/ | H9: 1 | I9: dentist hamilton nj | L9: Pending Semrush | N9: Large township (Hamilton Square, Mercerville, Yardville as sections). Several 'Hamilton' places exist: always write 'Hamilton, NJ'.
A10: Lawrence Township | B10: Mercer County NJ (new) | C10: 08648 | D10: 20-25 min | E10: US-1, I-295 | F10: Own page | G10: /dentist-lawrenceville-nj/ | H10: 2 | I10: dentist lawrenceville nj | L10: Pending Semrush | N10: Lawrenceville is the main village of Lawrence Twp.
A11: Hopewell Township (incl. Titusville, Washington Crossing NJ) | B11: Mercer County NJ (practice-listed) | C11: 08525, 08560 | D11: 15-20 min | E11: Washington Crossing Bridge, NJ-29 | F11: Own page | G11: /dentist-hopewell-nj/ | H11: 3 | I11: dentist hopewell nj | L11: Pending Semrush | N11: Practice lists 'Washington Crossing NJ'. It sits in Hopewell Twp (Titusville 08560), so it is a section here.
A12: Pennington | B12: Mercer County NJ (new) | C12: 08534 | D12: 20-25 min | E12: I-295, NJ-31 | F12: Own page | G12: /dentist-pennington-nj/ | H12: 3 | I12: dentist pennington nj | L12: Pending Semrush | N12: Small borough: keep the page short and genuinely local.
A13: Mercer County (regional) | B13: Mercer County NJ (new) | D13: 15-30 min | E13: US-1, I-295, NJ-29 | F13: Own page | G13: /dentist-mercer-county-nj/ | H13: 2 | I13: dentist mercer county nj | L13: Pending Semrush | M13: /dental-implants-mercer-county-nj/ | N13: Regional page: links to the 5 NJ town pages. Uses no town or ZIP terms itself.
A14: Newtown | B14: On hold | C14: 18940 | D14: 15-20 min | E14: PA-332, I-295 | F14: On hold | G14: /dentist-newtown-pa/ | H14: - | I14: dentist newtown pa | L14: Pending Semrush | N14: ON HOLD: Hampton Family Dental (your client) already has /areas-we-serve/dentist-newtown-pa/, and ASD's sitemap lists Newtown too. Practice lists Newtown. Confirm which client owns it.
A15: Langhorne | B15: On hold | C15: 19047 | D15: 10 min | E15: US-1, Oxford Valley Rd | F15: On hold | G15: /dentist-langhorne-pa/ | H15: - | I15: dentist langhorne pa | L15: Pending Semrush | N15: ON HOLD: ASD (your client) has Langhorne as a Tier 1 page + 3 service+town pages. Radiant is closer, but building it puts two clients in competition. Confirm.
A16: Levittown | B16: On hold | C16: 19054-19057 | D16: 10-15 min | E16: US-13, Oxford Valley Rd | F16: On hold | G16: /dentist-levittown-pa/ | H16: - | I16: dentist levittown pa | L16: Pending Semrush | N16: ON HOLD: ASD Tier 1 page. Practice lists Levittown. Confirm which client owns it.
A17: Fairless Hills | B17: On hold | C17: 19030 | D17: 10 min | E17: US-1, US-13 | F17: On hold | G17: /dentist-fairless-hills-pa/ | H17: - | I17: dentist fairless hills pa | L17: Pending Semrush | N17: ON HOLD: ASD Tier 1 page. Practice lists Fairless Hills. Tullytown would be a section of this page if released.
A18: Yardley Borough | B18: Home town | C18: 19067 | F18: Section of page | G18: / | N18: Homepage owns 'yardley dentist' and all Yardley + ZIP 19067 terms.
A19: Upper Makefield | B19: Bucks County PA | C19: 18940, 18977 | F19: Section of page | G19: /dentist-washington-crossing-pa/ | N19: Section of the Washington Crossing (PA) page.
A20: West Trenton | B20: Mercer County NJ | C20: 08628 | F20: Section of page | G20: /dentist-ewing-nj/ | N20: Section of the Ewing page.
A21: Titusville / Washington Crossing NJ | B21: Mercer County NJ | C21: 08560 | F21: Section of page | G21: /dentist-hopewell-nj/ | N21: Section of the Hopewell page.
A23: Service + town pages (conditional until Semrush shows demand)
A24: Service+town | F24: Conditional | G24: /dental-implants-mercer-county-nj/ | H24: 2 | I24: dental implants mercer county nj | L24: Pending Semrush | M24: Parent: /restorative-dentistry/dental-implants/ | N24: CONDITIONAL: build only if the Semrush rerun shows demand. Regional NJ page: why NJ patients cross the river for implants ($500 off, free consult, CareCredit). Must not copy the parent page.
A25: Service+town | F25: Conditional | G25: /emergency-dentist-trenton-nj/ | H25: 2 | I25: emergency dentist trenton nj | L25: Pending Semrush | M25: Parent: /emergency-dentistry/ | N25: CONDITIONAL: build only if the Semrush rerun shows demand. Route over the Trenton-Morrisville bridge, what to do before arriving, same-day booking. Do NOT claim 24/7 or Sunday care.
A26: Service+town | F26: Conditional | G26: /invisalign-trenton-nj/ | H26: 3 | I26: invisalign trenton nj | L26: Pending Semrush | M26: Parent: /cosmetic-dentistry/invisalign/ | N26: CONDITIONAL: build only if (1) certified Invisalign provider and (2) Semrush shows demand. Otherwise drop.
A27: Excluded | F27: Not targeted | N27: Princeton NJ, Robbinsville NJ, Bordentown NJ, Bristol PA, Penndel PA, Hulmeville PA: excluded (25-35 min, closer competitors, or already on ASD's plan). Southampton, Richboro, Holland, Warminster: Hampton Family Dental territory.

Sheet Keyword Clusters
A1: Page URL | B1: Hub | C1: Page | D1: Keyword | E1: Role | F1: Volume / mo | G1: KD | H1: Intent | I1: Where to use | J1: Source
A2: / | B2: Core | C2: Home | D2: dentist yardley pa | E2: Primary | F2: 480 | H2: Transactional (local) | I2: H1 + title tag + URL slug + first 100 words | J2: Agency report (Google Ads vol)
A3: / | B3: Core | C3: Home | D3: yardley dentist | E3: Local secondary | H3: Transactional (local) | I3: H2 or body copy, once each | J3: Pending Semrush
A4: / | B4: Core | C4: Home | D4: dentist in yardley pa | E4: Local secondary | H4: Transactional (local) | I4: H2 or body copy, once each | J4: Pending Semrush
A5: / | B5: Core | C5: Home | D5: dentist yardley | E5: Local secondary | H5: Transactional (local) | I5: H2 or body copy, once each | J5: Pending Semrush
A6: / | B6: Core | C6: Home | D6: dentist 19067 | E6: Local secondary | H6: Transactional (local) | I6: H2 or body copy, once each | J6: Pending Semrush
A7: / | B7: Core | C7: Home | D7: radiant smiles yardley | E7: Local secondary | H7: Transactional (local) | I7: H2 or body copy, once each | J7: Pending Semrush
A8: / | B8: Core | C8: Home | D8: dentist near me | E8: Near-me | F8: 823000 | G8: 67 | H8: Transactional (local) | I8: Title/meta wording + body; matches local-pack intent | J8: Semrush verified
A9: / | B9: Core | C9: Home | D9: family and cosmetic dentist yardley | E9: Long-tail | H9: Commercial / informational | I9: H3 or paragraph topic | J9: Pending Semrush
A10: /about-us/ | B10: Core | C10: About Us | D10: about radiant smiles yardley | E10: Primary | H10: Transactional (local) | I10: H1 + title tag + URL slug + first 100 words | J10: Pending Semrush
A11: /about-us/ | B11: Core | C11: About Us | D11: best dentist yardley | E11: Long-tail | H11: Commercial / informational | I11: H3 or paragraph topic | J11: Pending Semrush
A12: /about-us/dr-urvishkumar-bhalala/ | B12: Core | C12: Dr. Urvishkumar Bhalala | D12: dr urvishkumar bhalala | E12: Primary | H12: Transactional (local) | I12: H1 + title tag + URL slug + first 100 words | J12: Pending Semrush
A13: /about-us/dr-urvishkumar-bhalala/ | B13: Core | C13: Dr. Urvishkumar Bhalala | D13: dr bhalala dentist yardley | E13: Long-tail | H13: Commercial / informational | I13: H3 or paragraph topic | J13: Pending Semrush
A14: /about-us/dr-jaspreet-gadria-dmd/ | B14: Core | C14: Dr. Jaspreet Gadria | D14: dr jaspreet gadria | E14: Primary | H14: Transactional (local) | I14: H1 + title tag + URL slug + first 100 words | J14: Pending Semrush
A15: /about-us/dr-jaspreet-gadria-dmd/ | B15: Core | C15: Dr. Jaspreet Gadria | D15: dr gadria dentist yardley | E15: Long-tail | H15: Commercial / informational | I15: H3 or paragraph topic | J15: Pending Semrush
A16: /about-us/meet-the-staff/ | B16: Core | C16: Meet the Staff | D16: radiant smiles yardley team | E16: Primary | H16: Transactional (local) | I16: H1 + title tag + URL slug + first 100 words | J16: Pending Semrush
A17: /patient-reviews/ | B17: Core | C17: Patient Reviews | D17: radiant smiles floral vale reviews | E17: Primary | H17: Transactional (local) | I17: H1 + title tag + URL slug + first 100 words | J17: Pending Semrush
A18: /patient-reviews/ | B18: Core | C18: Patient Reviews | D18: yardley dentist reviews | E18: Long-tail | H18: Commercial / informational | I18: H3 or paragraph topic | J18: Pending Semrush
A19: /patient-reviews/ | B19: Core | C19: Patient Reviews | D19: dentist reviews | E19: National (context) | F19: 8100 | G19: 41 | H19: Mixed (national) | I19: Natural body mention only; not a ranking target | J19: Semrush verified
A20: /about-us/before-and-after-gallery/ | B20: Core | C20: Before & After Gallery | D20: smile makeover before and after | E20: Primary | F20: 480 | G20: 7 | H20: Transactional (local) | I20: H1 + title tag + URL slug + first 100 words | J20: Semrush verified
A21: /about-us/before-and-after-gallery/ | B21: Core | C21: Before & After Gallery | D21: veneers before and after | E21: Long-tail | H21: Commercial / informational | I21: H3 or paragraph topic | J21: Pending Semrush
A22: /about-us/before-and-after-gallery/ | B22: Core | C22: Before & After Gallery | D22: teeth whitening before and after | E22: Long-tail | H22: Commercial / informational | I22: H3 or paragraph topic | J22: Pending Semrush
A23: /about-us/before-and-after-gallery/ | B23: Core | C23: Before & After Gallery | D23: dental before and after | E23: National (context) | F23: 110 | G23: 0 | H23: Mixed (national) | I23: Natural body mention only; not a ranking target | J23: Semrush verified
A24: /special-offers/ | B24: Core | C24: Special Offers | D24: affordable dentist yardley | E24: Primary | H24: Transactional (local) | I24: H1 + title tag + URL slug + first 100 words | J24: Pending Semrush
A25: /special-offers/ | B25: Core | C25: Special Offers | D25: dentist no insurance near me | E25: Near-me | F25: 320 | G25: 24 | H25: Transactional (local) | I25: Title/meta wording + body; matches local-pack intent | J25: Semrush verified
A26: /special-offers/ | B26: Core | C26: Special Offers | D26: new patient dental special | E26: Secondary | F26: 50 | G26: 0 | H26: Commercial | I26: H2/H3 headings and body copy | J26: Semrush verified
A27: /special-offers/ | B27: Core | C27: Special Offers | D27: $89 new patient special dentist | E27: Long-tail | H27: Commercial / informational | I27: H3 or paragraph topic | J27: Pending Semrush
A28: /special-offers/ | B28: Core | C28: Special Offers | D28: dentist without insurance | E28: National (context) | F28: 2400 | G28: 41 | H28: Mixed (national) | I28: Natural body mention only; not a ranking target | J28: Semrush verified
A29: /contact-us/ | B29: Core | C29: Contact Us | D29: dental office yardley pa | E29: Primary | H29: Transactional (local) | I29: H1 + title tag + URL slug + first 100 words | J29: Pending Semrush
A30: /contact-us/ | B30: Core | C30: Contact Us | D30: dentist near me open late | E30: Near-me | F30: 140 | G30: 27 | H30: Transactional (local) | I30: Title/meta wording + body; matches local-pack intent | J30: Semrush verified
A31: /contact-us/ | B31: Core | C31: Contact Us | D31: dentist floral vale yardley | E31: Long-tail | H31: Commercial / informational | I31: H3 or paragraph topic | J31: Pending Semrush
A32: /patient-information/ | B32: Patient info | C32: Patient Information (hub) | D32: yardley dental office | E32: Primary | H32: Transactional (local) | I32: H1 + title tag + URL slug + first 100 words | J32: Pending Semrush
A33: /patient-information/new-patients/ | B33: Patient info | C33: New Patients | D33: dentist yardley accepting new patients | E33: Primary | H33: Transactional (local) | I33: H1 + title tag + URL slug + first 100 words | J33: Pending Semrush
A34: /patient-information/new-patients/ | B34: Patient info | C34: New Patients | D34: dentist accepting new patients near me | E34: Near-me | F34: 2400 | G34: 6 | H34: Transactional (local) | I34: Title/meta wording + body; matches local-pack intent | J34: Semrush verified
A35: /patient-information/new-patients/ | B35: Patient info | C35: New Patients | D35: new patient dentist near me | E35: Near-me | F35: 170 | G35: 59 | H35: Transactional (local) | I35: Title/meta wording + body; matches local-pack intent | J35: Semrush verified
A36: /patient-information/new-patients/ | B36: Patient info | C36: New Patients | D36: new patient dental exam | E36: Long-tail | H36: Commercial / informational | I36: H3 or paragraph topic | J36: Pending Semrush
A37: /patient-information/new-patients/ | B37: Patient info | C37: New Patients | D37: what to expect at first dentist appointment | E37: Long-tail | H37: Commercial / informational | I37: H3 or paragraph topic | J37: Pending Semrush
A38: /patient-information/new-patients/ | B38: Patient info | C38: New Patients | D38: what happens at a new patient dental visit | E38: Question | H38: Informational | I38: FAQ block (FAQPage schema) or H2 answer | J38: Pending Semrush
A39: /patient-information/scheduling/ | B39: Patient info | C39: Scheduling | D39: dentist appointment yardley | E39: Primary | H39: Transactional (local) | I39: H1 + title tag + URL slug + first 100 words | J39: Pending Semrush
A40: /patient-information/scheduling/ | B40: Patient info | C40: Scheduling | D40: same day dentist appointment | E40: Long-tail | H40: Commercial / informational | I40: H3 or paragraph topic | J40: Pending Semrush
...

Sheet Page Blueprint
A1: Page URL | B1: Primary keyword | C1: H1 | D1: Title tag (≤60) | E1: Title length | F1: Meta description (≤155) | G1: Meta length | H1: H2 outline | I1: Internal links | J1: Schema
A2: / | B2: dentist yardley pa | C2: Your Dentist in Yardley, PA for Healthy, Confident Smiles | D2: Dentist in Yardley, PA | Radiant Smiles @ Floral Vale | E2: 53 | F2: Family, cosmetic and restorative dentistry in Yardley, PA. $89 new-patient visit for uninsured patients. Call (215) 860-4600. | G2: 125 | H2: 1. Gentle family dentistry in Yardley 2. Our services: preventive, restorative, cosmetic, emergency 3. New patient special and offers 4. Meet Dr. Bhalala and Dr. Gadria 5. Patient reviews 6. Before & after gallery 7. Serving Yardley, Morrisville and nearby NJ towns 8. Book your visit | I2: /preventative-care/ /restorative-dentistry/ /cosmetic-dentistry/ /emergency-dentistry/ /special-offers/ /patient-reviews/ /contact-us/ | J2: Dentist (LocalBusiness), WebSite, BreadcrumbList
A3: /about-us/ | B3: about radiant smiles yardley | C3: About Radiant Smiles @ Floral Vale | D3: About Us | Radiant Smiles @ Floral Vale, Yardley PA | E3: 51 | F3: Meet the team behind Radiant Smiles @ Floral Vale in Yardley, PA: modern, comfortable family, cosmetic and restorative dentistry. | G3: 129 | H3: 1. Our approach to care 2. Meet our dentists 3. Meet the staff 4. Technology we use 5. Visit our Floral Vale office | I3: /about-us/dr-urvishkumar-bhalala/ /about-us/dr-jaspreet-gadria-dmd/ /about-us/meet-the-staff/ /patient-information/care-and-comfort/advanced-technology/ /contact-us/ | J3: AboutPage, Dentist, BreadcrumbList
A4: /about-us/dr-urvishkumar-bhalala/ | B4: dr urvishkumar bhalala | C4: Dr. Urvishkumar Bhalala, DMD | D4: Dr. Urvishkumar Bhalala, DMD | Yardley, PA Dentist | E4: 50 | F4: Meet Dr. Urvishkumar Bhalala, DMD, a dentist at Radiant Smiles @ Floral Vale in Yardley, PA. Book a visit today. | G4: 112 | H4: 1. About Dr. Bhalala 2. Education and training 3. Approach to patient care 4. Outside the office 5. Book with Dr. Bhalala | I4: /about-us/ /contact-us/ | J4: Person (Dentist), ProfilePage, BreadcrumbList
A5: /about-us/dr-jaspreet-gadria-dmd/ | B5: dr jaspreet gadria | C5: Dr. Jaspreet Gadria, DMD | D5: Dr. Jaspreet Gadria, DMD | Yardley, PA Dentist | E5: 46 | F5: Meet Dr. Jaspreet Gadria, DMD, a dentist at Radiant Smiles @ Floral Vale in Yardley, PA. Book a visit today. | G5: 108 | H5: 1. About Dr. Gadria 2. Education and training 3. Approach to patient care 4. Outside the office 5. Book with Dr. Gadria | I5: /about-us/ /contact-us/ | J5: Person (Dentist), ProfilePage, BreadcrumbList
A6: /about-us/meet-the-staff/ | B6: radiant smiles yardley team | C6: Meet Our Yardley Dental Team | D6: Meet the Staff | Radiant Smiles @ Floral Vale | E6: 45 | F6: Meet the hygienists, assistants and front-desk team at Radiant Smiles @ Floral Vale in Yardley, PA. | G6: 99 | H6: 1. Our hygienists 2. Our dental assistants 3. Our front desk | I6: /about-us/ /contact-us/ | J6: AboutPage, BreadcrumbList
A7: /patient-reviews/ | B7: radiant smiles floral vale reviews | C7: Patient Reviews | D7: Patient Reviews | Radiant Smiles @ Floral Vale, Yardley | E7: 55 | F7: Read what patients say about Radiant Smiles @ Floral Vale in Yardley, PA, then book your own visit. | G7: 99 | H7: 1. What our patients say 2. Leave us a review 3. Book your visit | I7: /contact-us/ /special-offers/ | J7: Dentist with Review markup only for first-party reviews, BreadcrumbList
A8: /about-us/before-and-after-gallery/ | B8: smile makeover before and after | C8: Before & After Smile Gallery | D8: Before & After Gallery | Radiant Smiles @ Floral Vale | E8: 53 | F8: See real before-and-after results from Radiant Smiles @ Floral Vale in Yardley, PA: veneers, whitening, implants and more. | G8: 122 | H8: 1. Smile makeovers 2. Veneers 3. Teeth whitening 4. Implants and restorations | I8: /cosmetic-dentistry/ /cosmetic-dentistry/dental-veneers-dentistry/ /restorative-dentistry/dental-implants/ | J8: ImageGallery, BreadcrumbList
A9: /special-offers/ | B9: affordable dentist yardley | C9: Dental Specials in Yardley, PA | D9: Dental Specials & New Patient Offer | Yardley, PA | E9: 49 | F9: $89 new-patient exam, cleaning and X-rays for uninsured patients, plus savings on implants, Invisalign and whitening. Call (215) 860-4600. | G9: 138 | H9: 1. $89 new patient visit 2. Dental implant savings 3. Invisalign savings 4. Teeth whitening savings 5. No insurance? Financing with CareCredit 6. Offer terms | I9: /restorative-dentistry/dental-implants/ /cosmetic-dentistry/invisalign/ /cosmetic-dentistry/teeth-whitening/ /patient-information/carecredit/ /contact-us/ | J9: Offer (within Dentist), FAQPage, BreadcrumbList
A10: /contact-us/ | B10: dental office yardley pa | C10: Contact Radiant Smiles @ Floral Vale | D10: Contact Us | Yardley, PA Dental Office | Radiant Smiles | E10: 55 | F10: Visit us at 117 Floral Vale Blvd, Yardley, PA 19067 or call (215) 860-4600. Hours, directions and online appointment requests. | G10: 126 | H10: 1. Call or request an appointment 2. Office hours 3. Directions to 117 Floral Vale Blvd 4. Parking and accessibility | I10: /patient-information/new-patients/ /special-offers/ | J10: Dentist (LocalBusiness), ContactPage, BreadcrumbList
A11: /patient-information/ | B11: yardley dental office | C11: Patient Information | D11: Patient Information | Radiant Smiles @ Floral Vale | E11: 50 | F11: Everything you need before your visit to Radiant Smiles @ Floral Vale in Yardley, PA: forms, insurance, financing and scheduling. | G11: 129 | H11: 1. New patients 2. Scheduling 3. Insurance and payment 4. Forms 5. Care and comfort | I11: /patient-information/new-patients/ /patient-information/scheduling/ /patient-information/insurance-payment-options/ /patient-information/patient-registration/ | J11: CollectionPage, BreadcrumbList
A12: /patient-information/new-patients/ | B12: dentist yardley accepting new patients | C12: New Patients Welcome in Yardley, PA | D12: New Patients | Yardley Dentist Accepting New Patients | E12: 53 | F12: Radiant Smiles @ Floral Vale is welcoming new patients in Yardley, PA. See what to expect at your first visit and book online or call (215) 860-4600. | G12: 149 | H12: 1. What to expect at your first visit 2. What to bring 3. $89 new patient special (uninsured) 4. Forms to fill in before you arrive 5. Book your first visit | I12: /patient-information/patient-registration/ /special-offers/ /patient-information/insurance-payment-options/ /contact-us/ | J12: MedicalWebPage, FAQPage, BreadcrumbList
A13: /patient-information/scheduling/ | B13: dentist appointment yardley | C13: Schedule Your Dental Appointment | D13: Schedule an Appointment | Yardley, PA Dentist | E13: 45 | F13: Request a dental appointment in Yardley, PA online or call (215) 860-4600. Emergency appointments available. | G13: 108 | H13: 1. Request an appointment 2. Office hours 3. Cancellation policy 4. Dental emergencies | I13: /emergency-dentistry/ /contact-us/ | J13: WebPage, BreadcrumbList
... A73: /invisalign-trenton-nj/ | B73: invisalign trenton nj | C73: Invisalign in Trenton, NJ | D73: Invisalign in Trenton, NJ | Radiant Smiles | E73: 42 | F73: Invisalign for patients from Trenton NJ, a short drive to Radiant Smiles @ Floral Vale in Yardley, PA. Call (215) 860-4600. | G73: 123 | H73: 1. Why NJ patients come to us 2. What to expect 3. Cost, offers and financing 4. Getting here 5. FAQs | I73: /cosmetic-dentistry/invisalign/ /areas-we-serve/ /dentist-trenton-nj/ /special-offers/ | J73: MedicalProcedure (or Service), Dentist (provider), FAQPage, BreadcrumbList, areaServed
A74: /disclaimer/ | B74: - | C74: Disclaimer | D74: Disclaimer | Radiant Smiles @ Floral Vale | E74: 41 | F74: - | G74: - | H74: - | I74: - | J74: WebPage
A75: /patient-information/terms/ | B75: - | C75: Terms | D75: Terms | Radiant Smiles @ Floral Vale | E75: 36 | F75: - | G75: - | H75: - | I75: - | J75: WebPage
A76: /patient-information/terms/privacy/ | B76: - | C76: Privacy Policy | D76: Privacy Policy | Radiant Smiles @ Floral Vale | E76: 45 | F76: - | G76: - | H76: - | I76: - | J76: WebPage
A77: /patient-information/terms/web-accessibility/ | B77: - | C77: Web Accessibility | D77: Web Accessibility | Radiant Smiles @ Floral Vale | E77: 48 | F77: - | G77: - | H77: - | I77: - | J77: WebPage
A78: /hipaa-notice-of-privacy-practices/ | B78: - | C78: HIPAA Notice of Privacy Practices | D78: HIPAA Notice | Radiant Smiles @ Floral Vale | E78: 43 | F78: - | G78: - | H78: - | I78: - | J78: WebPage

Sheet FAQ Bank
A1: Page URL | B1: Question / FAQ keyword | C1: Volume / mo | D1: KD | E1: Source | F1: Use
A2: /patient-information/new-patients/ | B2: what happens at a new patient dental visit | E2: Pending Semrush | F2: FAQ block + FAQPage schema
A3: /family-dentistry/ | B3: what is general dentistry | E3: Pending Semrush | F3: FAQ block + FAQPage schema
A4: /emergency-dentistry/ | B4: what is a dental emergency | E4: Pending Semrush | F4: FAQ block + FAQPage schema
A5: /preventative-care/teeth-cleaning-and-check-ups/ | B5: how often should you get your teeth cleaned | E5: Pending Semrush | F5: FAQ block + FAQPage schema
A6: /preventative-care/teeth-cleaning-and-check-ups/ | B6: are dental x rays safe | E6: Pending Semrush | F6: FAQ block + FAQPage schema
A7: /preventative-care/child-dentistry/ | B7: when should a child first see a dentist | E7: Pending Semrush | F7: FAQ block + FAQPage schema
A8: /preventative-care/dental-sealants/ | B8: are dental sealants worth it | E8: Pending Semrush | F8: FAQ block + FAQPage schema
A9: /preventative-care/fluoride/ | B9: is fluoride treatment necessary | E9: Pending Semrush | F9: FAQ block + FAQPage schema
A10: /preventative-care/deep-teeth-cleaning/ | B10: is deep cleaning necessary | E10: Pending Semrush | F10: FAQ block + FAQPage schema
A11: /preventative-care/gum-disease-laser-therapy/ | B11: does laser gum treatment hurt | E11: Pending Semrush | F11: FAQ block + FAQPage schema
A12: /restorative-dentistry/dental-implants/ | B12: how long do dental implants last | E12: Pending Semrush | F12: FAQ block + FAQPage schema
A13: /restorative-dentistry/dental-implants/ | B13: are dental implants painful | E13: Pending Semrush | F13: FAQ block + FAQPage schema
... A16: /restorative-dentistry/dentures/ | B16: how long do dentures last | E16: Pending Semrush | F16: FAQ block + FAQPage schema
A17: /cosmetic-dentistry/ | B17: how much does cosmetic dentistry cost | C17: 140 | D17: 13 | E17: Semrush verified | F17: FAQ block + FAQPage schema
A18: /cosmetic-dentistry/ | B18: what is cosmetic dentistry | C18: 1000 | D18: 13 | E18: Semrush verified | F18: FAQ block + FAQPage schema
A19: /cosmetic-dentistry/dental-veneers-dentistry/ | B19: how much are porcelain veneers | C19: 2400 | D19: 18 | E19: Semrush verified | F19: FAQ block + FAQPage schema
A20: /cosmetic-dentistry/dental-veneers-dentistry/ | B20: how long do porcelain veneers last | C20: 1300 | D20: 8 | E20: Semrush verified | F20: FAQ block + FAQPage schema
A21: /cosmetic-dentistry/dental-veneers-dentistry/ | B21: how to care for porcelain veneers | C21: 2400 | D21: 9 | E21: Semrush verified | F21: FAQ block + FAQPage schema
A22: /cosmetic-dentistry/teeth-whitening/ | B22: does teeth whitening hurt | E22: Pending Semrush | F22: FAQ block + FAQPage schema
A23: /cosmetic-dentistry/invisalign/ | B23: how long does invisalign take | E23: Pending Semrush | F23: FAQ block + FAQPage schema
A24: /cosmetic-dentistry/invisalign/invisalign-cost/ | B24: how much does invisalign cost | E24: Pending Semrush | F24: FAQ block + FAQPage schema
A25: /cosmetic-dentistry/invisalign/invisalign-cost/ | B25: does insurance cover invisalign | E25: Pending Semrush | F25: FAQ block + FAQPage schema
A26: /dentist-morrisville-pa/ | B26: How far is Radiant Smiles from Morrisville, PA? | E26: Town FAQ (write locally) | F26: FAQ block + FAQPage schema
A27: /dentist-morrisville-pa/ | B27: Do you accept patients from Morrisville, PA? | E27: Town FAQ (write locally) | F27: FAQ block + FAQPage schema
A28: /dentist-morrisville-pa/ | B28: Do you take my insurance? | E28: Town FAQ (write locally) | F28: FAQ block + FAQPage schema
A29: /dentist-lower-makefield-pa/ | B29: How far is Radiant Smiles from Lower Makefield, PA? | E29: Town FAQ (write locally) | F29: FAQ block + FAQPage schema
A30: /dentist-lower-makefield-pa/ | B30: Do you accept patients from Lower Makefield, PA? | E30: Town FAQ (write locally) | F30: FAQ block + FAQPage schema
A31: /dentist-lower-makefield-pa/ | B31: Do you take my insurance? | E31: Town FAQ (write locally) | F31: FAQ block + FAQPage schema
A32: /dentist-washington-crossing-pa/ | B32: How far is Radiant Smiles from Washington Crossing, PA? | E32: Town FAQ (write locally) | F32: FAQ block + FAQPage schema
A33: /dentist-washington-crossing-pa/ | B33: Do you accept patients from Washington Crossing, PA? | E33: Town FAQ (write locally) | F33: FAQ block + FAQPage schema
... A58: /dentist-mercer-county-nj/ | B58: Do you take my insurance? | E58: Town FAQ (write locally) | F58: FAQ block + FAQPage schema

Sheet Content Plan
A1: Order | B1: Page URL | C1: Page | D1: Hub | E1: Build tier | F1: Target words | G1: Primary keyword | H1: Primary vol / mo | I1: Best near-me opportunity | J1: Near-me vol | K1: Near-me KD | L1: Keywords in cluster | M1: Verified | N1: Pending
A2: 1 | B2: / | C2: Home | D2: Core | E2: 1 | F2: 900-1,200 | G2: dentist yardley pa | H2: 480 | I2: dentist near me | J2: 823,000 | K2: 67 | L2: 8 | M2: 2 | N2: 6
A3: 2 | B3: /emergency-dentistry/ | C3: Emergency Dentistry | D3: General dentistry | E3: 1 | F3: 1,200-1,500 | G3: emergency dentist yardley | I3: emergency dentist near me | J3: 135,000 | K3: 11 | L3: 14 | M3: 5 | N3: 9
A4: 3 | B4: /restorative-dentistry/dental-implants/ | C4: Dental Implants | D4: Restorative | E4: 1 | F4: 1,500-2,000 | G4: dental implants yardley pa | H4: 10 | I4: dental implants near me | J4: 110,000 | K4: 32 | L4: 9 | M4: 3 | N4: 6
A5: 4 | B5: /cosmetic-dentistry/invisalign/ | C5: Invisalign | D5: Cosmetic | E5: 1 | F5: 1,200-1,500 | G5: invisalign yardley pa | H5: 10 | I5: invisalign near me | J5: 110,000 | K5: 45 | L5: 8 | M5: 5 | N5: 3
A6: 5 | B6: /preventative-care/child-dentistry/ | C6: Child Dentistry | D6: Preventative care | E6: 1 | F6: 1,000-1,300 | G6: childrens dentist yardley | I6: pediatric dentist near me | J6: 90,500 | K6: 42 | L6: 7 | M6: 4 | N6: 3
A7: 6 | B7: /preventative-care/teeth-cleaning-and-check-ups/ | C7: Teeth Cleaning & Check-ups | D7: Preventative care | E7: 1 | F7: 1,000-1,300 | G7: dental cleaning yardley | I7: teeth cleaning near me | J7: 60,500 | K7: 6 | L7: 12 | M7: 5 | N7: 7
A8: 7 | B8: /restorative-dentistry/root-canal/ | C8: Root Canal Therapy | D8: Restorative | E8: 1 | F8: 1,200-1,500 | G8: root canal yardley pa | I8: root canal near me | J8: 60,500 | K8: 10 | L8: 6 | M8: 3 | N8: 3
A9: 8 | B9: /restorative-dentistry/tooth-extractions/ | C9: Tooth Extractions | D9: Restorative | E9: 1 | F9: 1,000-1,300 | G9: tooth extraction yardley | I9: tooth extraction near me | J9: 60,500 | K9: 48 | L9: 5 | M9: 2 | N9: 3
A10: 9 | B10: /restorative-dentistry/dentures/ | C10: Dentures | D10: Restorative | E10: 1 | F10: 1,200-1,500 | G10: dentures yardley pa | I10: dentures near me | J10: 60,500 | K10: 58 | L10: 5 | M10: 2 | N10: 3
A11: 10 | B11: /cosmetic-dentistry/teeth-whitening/ | C11: Teeth Whitening | D11: Cosmetic | E11: 1 | F11: 1,000-1,300 | G11: teeth whitening yardley pa | H11: 10 | I11: teeth whitening near me | J11: 60,500 | K11: 6 | L11: 6 | M11: 4 | N11: 2
A12: 11 | B12: /family-dentistry/ | C12: Family Dentistry | D12: General dentistry | E12: 1 | F12: 1,000-1,300 | G12: family dentist yardley pa | I12: family dentist near me | J12: 49,500 | K12: 50 | L12: 8 | M12: 4 | N12: 4
A13: 12 | B13: /cosmetic-dentistry/ | C13: Cosmetic Dentistry (hub) | D13: Cosmetic | E13: 1 | F13: 1,500-2,000 | G13: cosmetic dentist yardley pa | I13: cosmetic dentist near me | J13: 49,500 | K13: 33 | L13: 10 | M13: 8 | N13: 2
A14: 13 | B14: /cosmetic-dentistry/dental-veneers-dentistry/ | C14: Veneers | D14: Cosmetic | E14: 1 | F14: 1,300-1,600 | G14: porcelain veneers yardley pa | H14: 10 | I14: veneers near me | J14: 49,500 | K14: 5 | L14: 11 | M14: 10 | N14: 1
A15: 14 | B15: /restorative-dentistry/dental-crowns/ | C15: Dental Crowns | D15: Restorative | E15: 1 | F15: 1,000-1,300 | G15: dental crowns yardley pa | I15: dental crown near me | J15: 14,800 | K15: 4 | L15: 6 | M15: 3 | N15: 3
A16: 15 | B16: /restorative-dentistry/periodontal-services/ | C16: Periodontal Services | D16: Restorative | E16: 1 | F16: 1,000-1,300 | G16: gum disease treatment yardley | I16: gum disease treatment near me | J16: 2,900 | K16: 5 | L16: 6 | M16: 1 | N16: 5
A17: 16 | B17: /patient-information/new-patients/ | C17: New Patients | D17: Patient info | E17: 1 | F17: 600-800 | G17: dentist yardley accepting new patients | I17: dentist accepting new patients near me | J17: 2,400 | K17: 6 | L17: 6 | M17: 2 | N17: 4
A18: 17 | B18: /restorative-dentistry/ | C18: Restorative Dentistry (hub) | D18: Restorative | E18: 1 | F18: 1,500-2,000 | G18: restorative dentist yardley | I18: restorative dentist near me | J18: 1,900 | K18: 14 | L18: 3 | M18: 2 | N18: 1
A19: 18 | B19: /special-offers/ | C19: Special Offers | D19: Core | E19: 1 | F19: 500-800 | G19: affordable dentist yardley | I19: dentist no insurance near me | J19: 320 | K19: 24 | L19: 5 | M19: 3 | N19: 2
A20: 19 | B20: /patient-information/carecredit/ | C20: CareCredit | D20: Patient info | E20: 1 | F20: 500-700 | G20: dental financing yardley | I20: dental financing near me | J20: 170 | K20: 9 | L20: 6 | M20: 4 | N20: 2
A21: 20 | B21: /contact-us/ | C21: Contact Us | D21: Core | E21: 1 | F21: 200-400 | G21: dental office yardley pa | I21: dentist near me open late | J21: 140 | K21: 27 | L21: 3 | M21: 1 | N21: 2
A22: 21 | B22: /patient-information/insurance-payment-options/ | C22: Insurance & Payment | D22: Patient info | E22: 1 | F22: 500-700 | G22: dentist that accepts ppo yardley | I22: dental insurance accepted near me | J22: 20 | K22: 0 | L22: 6 | M22: 2 | N22: 4
A23: 22 | B23: /about-us/ | C23: About Us | D23: Core | E23: 1 | F23: 500-700 | G23: about radiant smiles yardley | I23: - | L23: 2 | M23: 0 | N23: 2
A24: 23 | B24: /about-us/dr-urvishkumar-bhalala/ | C24: Dr. Urvishkumar Bhalala | D24: Core | E24: 1 | F24: 400-600 | G24: dr urvishkumar bhalala | I24: - | L24: 2 | M24: 0 | N24: 2
A25: 24 | B25: /about-us/dr-jaspreet-gadria-dmd/ | C25: Dr. Jaspreet Gadria | D25: Core | E25: 1 | F25: 400-600 | G25: dr jaspreet gadria | I25: - | L25: 2 | M25: 0 | N25: 2
A26: 25 | B26: /patient-reviews/ | C26: Patient Reviews | D26: Core | E26: 1 | F26: 300-500 + reviews | G26: radiant smiles floral vale reviews | I26: - | L26: 3 | M26: 1 | N26: 2
A27: 26 | B27: /patient-information/ | C27: Patient Information (hub) | D27: Patient info | E27: 1 | F27: 400-600 | G27: yardley dental office | I27: - | L27: 1 | M27: 0 | N27: 1
A28: 27 | B28: /patient-information/scheduling/ | C28: Scheduling | D28: Patient info | E28: 1 | F28: 300-500 | G28: dentist appointment yardley | I28: - | L28: 2 | M28: 0 | N28: 2
A29: 28 | B29: /patient-information/patient-registration/ | C29: Patient Registration | D29: Patient info | E29: 1 | F29: 200-400 | G29: radiant smiles patient forms | I29: - | L29: 1 | M29: 0 | N29: 1
A30: 29 | B30: /preventative-care/ | C30: Preventative Care (hub) | D30: Preventative care | E30: 1 | F30: 1,000-1,500 | G30: preventive dentistry yardley | I30: - | L30: 3 | M30: 0 | N30: 3
A31: 30 | B31: /restorative-dentistry/dentures/implant-retained-dentures/ | C31: Implant-Retained Dentures | D31: Restorative | E31: 1 | F31: 900-1,200 | G31: implant dentures yardley | I31: implant supported dentures near me | J31: No data (unverified) | K31: - | L31: 4 | M31: 0 | N31: 4
A32: 31 | B32: /cosmetic-dentistry/invisalign/invisalign-cost/ | C32: Invisalign Cost | D32: Cosmetic | E32: 1 | F32: 800-1,000 | G32: invisalign cost yardley | I32: - | L32: 4 | M32: 0 | N32: 4
A33: 32 | B33: /areas-we-serve/ | C33: Areas We Serve (hub) | D33: Location | E33: 1 | F33: 700-1,000 | G33: dentist near trenton nj | I33: - | L33: 2 | M33: 0 | N33: 2
A34: 33 | B34: /dentist-morrisville-pa/ | C34: Dentist near Morrisville, PA | D34: Location | E34: 1 | F34: 900-1,200 | G34: dentist morrisville pa | I34: - | L34: 5 | M34: 0 | N34: 5
A35: 34 | B35: /dentist-trenton-nj/ | C35: Dentist near Trenton, NJ | D35: Location | E35: 1 | F35: 900-1,200 | G35: dentist trenton nj | I35: - | L35: 7 | M35: 0 | N35: 7
A36: 35 | B36: /dentist-ewing-nj/ | C36: Dentist near Ewing, NJ | D36: Location | E36: 1 | F36: 900-1,200 | G36: dentist ewing nj | I36: - | L36: 5 | M36: 0 | N36: 5
A37: 36 | B37: /dentist-hamilton-nj/ | C37: Dentist near Hamilton, NJ | D37: Location | E37: 1 | F37: 900-1,200 | G37: dentist hamilton nj | I37: - | L37: 5 | M37: 0 | N37: 5
A38: 37 | B38: /restorative-dentistry/wisdom-teeth-removal/ | C38: Wisdom Teeth Removal | D38: Restorative | E38: 2 | F38: 900-1,200 | G38: wisdom teeth removal yardley | I38: wisdom teeth removal near me | J38: 27,100 | K38: 52 | L38: 4 | M38: 2 | N38: 2
A39: 38 | B39: /preventative-care/dental-sealants/ | C39: Dental Sealants | D39: Preventative care | E39: 2 | F39: 700-900 | G39: dental sealants yardley | I39: dental sealants near me | J39: 6,600 | K39: 7 | L39: 4 | M39: 2 | N39: 2
A40: 39 | B40: /cosmetic-dentistry/dental-bonding/ | C40: Dental Bonding | D40: Cosmetic | E40: 2 | F40: 900-1,200 | G40: dental bonding yardley | I40: dental bonding near me | J40: 4,400 | K40: 3 | L40: 5 | M40: 2 | N40: 3
...
